ProgrammingError
sqlalchemy.exc.ProgrammingError: (psycopg2.errors.UndefinedColumn) column property.video_data does not exist
LINE 1: ...path, property.video_path AS property_video_path, property.v...
                                                             ^
HINT:  Perhaps you meant to reference the column "property.video_path".

[SQL: SELECT property.id AS property_id, property.title AS property_title, property.description AS property_description, property.image_path AS property_image_path, property.video_path AS property_video_path, property.video_data AS property_video_data, property.video_filename AS property_video_filename, property.video_content_type AS property_video_content_type, property.property_type AS property_property_type, property.price AS property_price, property.location AS property_location, property.created_at AS property_created_at, property.featured AS property_featured 
FROM property ORDER BY property.created_at DESC 
 LIMIT %(param_1)s]
[parameters: {'param_1': 3}]
(Background on this error at: https://sqlalche.me/e/20/f405)

Traceback (most recent call last)
File "/opt/venv/lib/python3.12/site-packages/sqlalchemy/engine/base.py", line 1967, in _exec_single_context
self.dialect.do_execute(
^
File "/opt/venv/lib/python3.12/site-packages/sqlalchemy/engine/default.py", line 951, in do_execute
cursor.execute(statement, parameters)
^^^^^^^^^^^^^^^^^^^^^^^^^^^^^^^^^^^^^
The above exception was the direct cause of the following exception:
File "/opt/venv/lib/python3.12/site-packages/flask/app.py", line 1536, in __call__
return self.wsgi_app(environ, start_response)
       ^^^^^^^^^^^^^^^^^^^^^^^^^^^^^^^^^^^^^^
File "/opt/venv/lib/python3.12/site-packages/werkzeug/middleware/proxy_fix.py", line 183, in __call__
return self.app(environ, start_response)
       ^^^^^^^^^^^^^^^^^^^^^^^^^^^^^^^^^
File "/opt/venv/lib/python3.12/site-packages/flask/app.py", line 1514, in wsgi_app
response = self.handle_exception(e)
           ^^^^^^^^^^^^^^^^^^^^^^^^
File "/opt/venv/lib/python3.12/site-packages/flask/app.py", line 1511, in wsgi_app
response = self.full_dispatch_request()
           ^^^^^^^^^^^^^^^^^^^^^^^^^^^^
File "/opt/venv/lib/python3.12/site-packages/flask/app.py", line 919, in full_dispatch_request
rv = self.handle_user_exception(e)
     ^^^^^^^^^^^^^^^^^^^^^^^^^^^^^
File "/opt/venv/lib/python3.12/site-packages/flask/app.py", line 917, in full_dispatch_request
rv = self.dispatch_request()
     ^^^^^^^^^^^^^^^^^^^^^^^
File "/opt/venv/lib/python3.12/site-packages/flask/app.py", line 902, in dispatch_request
return self.ensure_sync(self.view_functions[rule.endpoint])(**view_args)  # type: ignore[no-any-return]
       ^^^^^^^^^^^^^^^^^^^^^^^^^^^^^^^^^^^^^^^^^^^^^^^^^^^^^^^^^^^^^^^^^
File "/app/routes.py", line 25, in index
recent_properties = Property.query.order_by(Property.created_at.desc()).limit(3).all()
                    ^^^^^^^^^^^^^^^^^^^^^^^^^^^^^^^^^^^^^^^^^^^^^^^^^^^^^^^^^^^^^^^^^^
File "/opt/venv/lib/python3.12/site-packages/sqlalchemy/orm/query.py", line 2704, in all
return self._iter().all()  # type: ignore
       ^^^^^^^^^^^^
File "/opt/venv/lib/python3.12/site-packages/sqlalchemy/orm/query.py", line 2857, in _iter
result: Union[ScalarResult[_T], Result[_T]] = self.session.execute(
                                              
File "/opt/venv/lib/python3.12/site-packages/sqlalchemy/orm/session.py", line 2365, in execute
return self._execute_internal(
       
File "/opt/venv/lib/python3.12/site-packages/sqlalchemy/orm/session.py", line 2251, in _execute_internal
result: Result[Any] = compile_state_cls.orm_execute_statement(
                      
File "/opt/venv/lib/python3.12/site-packages/sqlalchemy/orm/context.py", line 306, in orm_execute_statement
result = conn.execute(
         
File "/opt/venv/lib/python3.12/site-packages/sqlalchemy/engine/base.py", line 1419, in execute
return meth(
       
File "/opt/venv/lib/python3.12/site-packages/sqlalchemy/sql/elements.py", line 526, in _execute_on_connection
return connection._execute_clauseelement(
       
File "/opt/venv/lib/python3.12/site-packages/sqlalchemy/engine/base.py", line 1641, in _execute_clauseelement
ret = self._execute_context(
      
File "/opt/venv/lib/python3.12/site-packages/sqlalchemy/engine/base.py", line 1846, in _execute_context
return self._exec_single_context(
       
File "/opt/venv/lib/python3.12/site-packages/sqlalchemy/engine/base.py", line 1986, in _exec_single_context
self._handle_dbapi_exception(
^
File "/opt/venv/lib/python3.12/site-packages/sqlalchemy/engine/base.py", line 2355, in _handle_dbapi_exception
raise sqlalchemy_exception.with_traceback(exc_info[2]) from e
^^^^^^^^^^^^^^^^^^^^^^^^^^^^^^^^^^^^^^^^^^^^^^^^^^^^^^^^^^^^^
File "/opt/venv/lib/python3.12/site-packages/sqlalchemy/engine/base.py", line 1967, in _exec_single_context
self.dialect.do_execute(
^
File "/opt/venv/lib/python3.12/site-packages/sqlalchemy/engine/default.py", line 951, in do_execute
cursor.execute(statement, parameters)
^^^^^^^^^^^^^^^^^^^^^^^^^^^^^^^^^^^^^
sqlalchemy.exc.ProgrammingError: (psycopg2.errors.UndefinedColumn) column property.video_data does not exist
LINE 1: ...path, property.video_path AS property_video_path, property.v...
^
HINT: Perhaps you meant to reference the column "property.video_path".

[SQL: SELECT property.id AS property_id, property.title AS property_title, property.description AS property_description, property.image_path AS property_image_path, property.video_path AS property_video_path, property.video_data AS property_video_data, property.video_filename AS property_video_filename, property.video_content_type AS property_video_content_type, property.property_type AS property_property_type, property.price AS property_price, property.location AS property_location, property.created_at AS property_created_at, property.featured AS property_featured
FROM property ORDER BY property.created_at DESC
LIMIT %(param_1)s]
[parameters: {'param_1': 3}]
(Background on this error at: https://sqlalche.me/e/20/f405)
The debugger caught an exception in your WSGI application. You can now look at the traceback which led to the error.
To switch between the interactive traceback and the plaintext one, you can click on the "Traceback" headline. From the text traceback you can also create a paste of it.

